Workbook

Sheet 5_2
B1: 170 | C1: 175 | D1: 180 | E1: 185 | F1: 190 | G1: 195
A2: 170 | B2: 1 | C2: {=1/INDEX($B$2:$G$7,COLUMN(C2)-COLUMN($B$2)+1,ROW(C2)-ROW($B$2)+1)} -> 0.5 | D2: {=1/INDEX($B$2:$G$7,COLUMN(D2)-COLUMN($B$2)+1,ROW(D2)-ROW($B$2)+1)} -> 0.25 | E2: {=1/INDEX($B$2:$G$7,COLUMN(E2)-COLUMN($B$2)+1,ROW(E2)-ROW($B$2)+1)} -> 0.16666667 | F2: {=1/INDEX($B$2:$G$7,COLUMN(F2)-COLUMN($B$2)+1,ROW(F2)-ROW($B$2)+1)} -> 0.125 | G2: {=1/INDEX($B$2:$G$7,COLUMN(G2)-COLUMN($B$2)+1,ROW(G2)-ROW($B$2)+1)} -> 0.11111111
A3: 175 | B3: 2 | C3: 1 | D3: {=1/INDEX($B$2:$G$7,COLUMN(D3)-COLUMN($B$2)+1,ROW(D3)-ROW($B$2)+1)} -> 0.33333333 | E3: {=1/INDEX($B$2:$G$7,COLUMN(E3)-COLUMN($B$2)+1,ROW(E3)-ROW($B$2)+1)} -> 0.2 | F3: {=1/INDEX($B$2:$G$7,COLUMN(F3)-COLUMN($B$2)+1,ROW(F3)-ROW($B$2)+1)} -> 0.14285714 | G3: {=1/INDEX($B$2:$G$7,COLUMN(G3)-COLUMN($B$2)+1,ROW(G3)-ROW($B$2)+1)} -> 0.125
A4: 180 | B4: 4 | C4: 3 | D4: 1 | E4: {=1/INDEX($B$2:$G$7, COLUMN(E4)-1, ROW(E4)-1)} -> 0.25 | F4: {=1/INDEX($B$2:$G$7,COLUMN(F4)-COLUMN($B$2)+1,ROW(F4)-ROW($B$2)+1)} -> 0.25 | G4: {=1/INDEX($B$2:$G$7,COLUMN(G4)-COLUMN($B$2)+1,ROW(G4)-ROW($B$2)+1)} -> 0.2
A5: 185 | B5: 6 | C5: 5 | D5: 4 | E5: 1 | F5: {=1/INDEX($B$2:$G$7,COLUMN(F5)-COLUMN($B$2)+1,ROW(F5)-ROW($B$2)+1)} -> 0.33333333 | G5: {=1/INDEX($B$2:$G$7,COLUMN(G5)-COLUMN($B$2)+1,ROW(G5)-ROW($B$2)+1)} -> 0.33333333
A6: 190 | B6: 8 | C6: 7 | D6: 4 | E6: 3 | F6: 1 | G6: {=1/INDEX($B$2:$G$7,COLUMN(G6)-COLUMN($B$2)+1,ROW(G6)-ROW($B$2)+1)} -> 1
A7: 195 | B7: 9 | C7: 8 | D7: 5 | E7: 3 | F7: 1 | G7: 1
B15: 160 | C15: =B15+5 -> 165 | D15: =C15+5 -> 170 | E15: =D15+5 -> 175 | F15: =E15+5 -> 180 | G15: =F15+5 -> 185 | H15: =G15+5 -> 190 | I15: =H15+5 -> 195 | J15: =I15+5 -> 200
A16: 160 | B16: 1 | C16: {=1/INDEX('lab6'!$D$8:$O$19, COLUMN(C16)-COLUMN($B$16)+1, ROW(C16)-ROW($B$16)+1)} -> 1 | D16: {=1/INDEX($B$16:$J$24, COLUMN(D16)-COLUMN($B$16)+1, ROW(D16)-ROW($B$16)+1)} -> 0.33333333 | E16: {=1/INDEX($B$16:$J$24, COLUMN(E16)-COLUMN($B$16)+1, ROW(E16)-ROW($B$16)+1)} -> 0.25 | F16: {=1/INDEX($B$16:$J$24, COLUMN(F16)-COLUMN($B$16)+1, ROW(F16)-ROW($B$16)+1)} -> 0.2 | G16: {=1/INDEX($B$16:$J$24, COLUMN(G16)-COLUMN($B$16)+1, ROW(G16)-ROW($B$16)+1)} -> 0.16666667 | H16: {=1/INDEX($B$16:$J$24, COLUMN(H16)-COLUMN($B$16)+1, ROW(H16)-ROW($B$16)+1)} -> 0.14285714 | I16: {=1/INDEX($B$16:$J$24, COLUMN(I16)-COLUMN($B$16)+1, ROW(I16)-ROW($B$16)+1)} -> 0.125 | J16: {=1/INDEX($B$16:$J$24, COLUMN(J16)-COLUMN($B$16)+1, ROW(J16)-ROW($B$16)+1)} -> 0.11111111
A17: =A16+5 -> 165 | B17: 2 | C17: 1 | D17: {=1/INDEX($B$16:$J$24, COLUMN(D17)-COLUMN($B$16)+1, ROW(D17)-ROW($B$16)+1)} -> 0.5 | E17: {=1/INDEX($B$16:$J$24, COLUMN(E17)-COLUMN($B$16)+1, ROW(E17)-ROW($B$16)+1)} -> 0.25 | F17: {=1/INDEX($B$16:$J$24, COLUMN(F17)-COLUMN($B$16)+1, ROW(F17)-ROW($B$16)+1)} -> 0.2 | G17: {=1/INDEX($B$16:$J$24, COLUMN(G17)-COLUMN($B$16)+1, ROW(G17)-ROW($B$16)+1)} -> 0.16666667 | H17: {=1/INDEX($B$16:$J$24, COLUMN(H17)-COLUMN($B$16)+1, ROW(H17)-ROW($B$16)+1)} -> 0.14285714 | I17: {=1/INDEX($B$16:$J$24, COLUMN(I17)-COLUMN($B$16)+1, ROW(I17)-ROW($B$16)+1)} -> 0.125 | J17: {=1/INDEX($B$16:$J$24, COLUMN(J17)-COLUMN($B$16)+1, ROW(J17)-ROW($B$16)+1)} -> 0.11111111
A18: =A17+5 -> 170 | B18: 3 | C18: 2 | D18: 1 | E18: {=1/INDEX($B$16:$J$24, COLUMN(E18)-COLUMN($B$16)+1, ROW(E18)-ROW($B$16)+1)} -> 0.5 | F18: {=1/INDEX($B$16:$J$24, COLUMN(F18)-COLUMN($B$16)+1, ROW(F18)-ROW($B$16)+1)} -> 0.25 | G18: {=1/INDEX($B$16:$J$24, COLUMN(G18)-COLUMN($B$16)+1, ROW(G18)-ROW($B$16)+1)} -> 0.2 | H18: {=1/INDEX($B$16:$J$24, COLUMN(H18)-COLUMN($B$16)+1, ROW(H18)-ROW($B$16)+1)} -> 0.16666667 | I18: {=1/INDEX($B$16:$J$24, COLUMN(I18)-COLUMN($B$16)+1, ROW(I18)-ROW($B$16)+1)} -> 0.14285714 | J18: {=1/INDEX($B$16:$J$24, COLUMN(J18)-COLUMN($B$16)+1, ROW(J18)-ROW($B$16)+1)} -> 0.125
A19: =A18+5 -> 175 | B19: 4 | C19: 4 | D19: 2 | E19: 1 | F19: {=1/INDEX($B$16:$J$24, COLUMN(F19)-COLUMN($B$16)+1, ROW(F19)-ROW($B$16)+1)} -> 0.33333333 | G19: {=1/INDEX($B$16:$J$24, COLUMN(G19)-COLUMN($B$16)+1, ROW(G19)-ROW($B$16)+1)} -> 0.2 | H19: {=1/INDEX($B$16:$J$24, COLUMN(H19)-COLUMN($B$16)+1, ROW(H19)-ROW($B$16)+1)} -> 0.14285714 | I19: {=1/INDEX($B$16:$J$24, COLUMN(I19)-COLUMN($B$16)+1, ROW(I19)-ROW($B$16)+1)} -> 0.125 | J19: {=1/INDEX($B$16:$J$24, COLUMN(J19)-COLUMN($B$16)+1, ROW(J19)-ROW($B$16)+1)} -> 0.125
A20: =A19+5 -> 180 | B20: 5 | C20: 5 | D20: 4 | E20: 3 | F20: 1 | G20: {=1/INDEX($B$16:$J$24, COLUMN(G20)-COLUMN($B$16)+1, ROW(G20)-ROW($B$16)+1)} -> 0.25 | H20: {=1/INDEX($B$16:$J$24, COLUMN(H20)-COLUMN($B$16)+1, ROW(H20)-ROW($B$16)+1)} -> 0.16666667 | I20: {=1/INDEX($B$16:$J$24, COLUMN(I20)-COLUMN($B$16)+1, ROW(I20)-ROW($B$16)+1)} -> 0.125 | J20: {=1/INDEX($B$16:$J$24, COLUMN(J20)-COLUMN($B$16)+1, ROW(J20)-ROW($B$16)+1)} -> 0.11111111
A21: =A20+5 -> 185 | B21: 6 | C21: 6 | D21: 5 | E21: 5 | F21: 4 | G21: 1 | H21: {=1/INDEX($B$16:$J$24, COLUMN(H21)-COLUMN($B$16)+1, ROW(H21)-ROW($B$16)+1)} -> 0.33333333 | I21: {=1/INDEX($B$16:$J$24, COLUMN(I21)-COLUMN($B$16)+1, ROW(I21)-ROW($B$16)+1)} -> 0.25 | J21: {=1/INDEX($B$16:$J$24, COLUMN(J21)-COLUMN($B$16)+1, ROW(J21)-ROW($B$16)+1)} -> 0.2
A22: =A21+5 -> 190 | B22: 7 | C22: 7 | D22: 6 | E22: 7 | F22: 6 | G22: 3 | H22: 1 | I22: {=1/INDEX($B$16:$J$24, COLUMN(I22)-COLUMN($B$16)+1, ROW(I22)-ROW($B$16)+1)} -> 0.5 | J22: {=1/INDEX($B$16:$J$24, COLUMN(J22)-COLUMN($B$16)+1, ROW(J22)-ROW($B$16)+1)} -> 0.33333333
A23: 185 | B23: 8 | C23: 8 | D23: 7 | E23: 8 | F23: 8 | G23: 4 | H23: 2 | I23: 1 | J23: {=1/INDEX($B$16:$J$24, COLUMN(J23)-COLUMN($B$16)+1, ROW(J23)-ROW($B$16)+1)} -> 1
A24: =A23+5 -> 190 | B24: 9 | C24: 9 | D24: 8 | E24: 8 | F24: 9 | G24: 5 | H24: 3 | I24: 1 | J24: 1

Sheet lab6
A1: Перменная "Температура на улице", термы - "холодно", "прохладно", "умеренно", "тепло", "жарко".
C6: Таблица попарных сравнений по отношению к свойству "холодно"
D7: -20 | E7: -15 | F7: =E7+5 -> -10 | G7: =F7+5 -> -5 | H7: =G7+5 -> 0 | I7: =H7+5 -> 5 | J7: =I7+5 -> 10 | K7: =J7+5 -> 15 | L7: =K7+5 -> 20 | M7: =L7+5 -> 25 | ... O7: =N7+5 -> 35
C8: =-20 -> -20 | D8: 1 | E8: 1 | F8: 2 | G8: 3 | H8: 4 | I8: 5 | J8: 6 | K8: 7 | L8: 8 | M8: 8 | N8: 9 | O8: 9
C9: =C8+5 -> -15 | D9: {=1/INDEX($D$8:$O$19,COLUMN(D9)-COLUMN($D$8)+1,ROW(D9)-ROW($D$8)+1)} -> 1 | E9: 1 | F9: 2 | G9: 2 | H9: 3 | I9: 4 | J9: 5 | K9: 6 | L9: 7 | M9: 8 | N9: 8 | O9: 9
C10: =C9+5 -> -10 | D10: {=1/INDEX($D$8:$O$19,COLUMN(D10)-COLUMN($D$8)+1,ROW(D10)-ROW($D$8)+1)} -> 0.5 | E10: {=1/INDEX($D$8:$O$19,COLUMN(E10)-COLUMN($D$8)+1,ROW(E10)-ROW($D$8)+1)} -> 0.5 | F10: 1 | G10: 3 | H10: 4 | I10: 4 | J10: 4 | K10: 5 | L10: 6 | M10: 7 | N10: 8 | O10: 9
C11: =C10+5 -> -5 | D11: {=1/INDEX($D$8:$O$19,COLUMN(D11)-COLUMN($D$8)+1,ROW(D11)-ROW($D$8)+1)} -> 0.33333333 | E11: {=1/INDEX($D$8:$O$19,COLUMN(E11)-COLUMN($D$8)+1,ROW(E11)-ROW($D$8)+1)} -> 0.5 | F11: {=1/INDEX($D$8:$O$19,COLUMN(F11)-COLUMN($D$8)+1,ROW(F11)-ROW($D$8)+1)} -> 0.33333333 | G11: 1 | H11: 4 | I11: 5 | J11: 5 | K11: 6 | L11: 6 | M11: 7 | N11: 8 | O11: 9
C12: =C11+5 -> 0 | D12: {=1/INDEX($D$8:$O$19,COLUMN(D12)-COLUMN($D$8)+1,ROW(D12)-ROW($D$8)+1)} -> 0.25 | E12: {=1/INDEX($D$8:$O$19,COLUMN(E12)-COLUMN($D$8)+1,ROW(E12)-ROW($D$8)+1)} -> 0.33333333 | F12: {=1/INDEX($D$8:$O$19,COLUMN(F12)-COLUMN($D$8)+1,ROW(F12)-ROW($D$8)+1)} -> 0.25 | G12: {=1/INDEX($D$8:$O$19,COLUMN(G12)-COLUMN($D$8)+1,ROW(G12)-ROW($D$8)+1)} -> 0.25 | H12: 1 | I12: 4 | J12: 4 | K12: 5 | L12: 6 | M12: 7 | N12: 7 | O12: 8
C13: =C12+5 -> 5 | D13: {=1/INDEX($D$8:$O$19,COLUMN(D13)-COLUMN($D$8)+1,ROW(D13)-ROW($D$8)+1)} -> 0.2 | E13: {=1/INDEX($D$8:$O$19,COLUMN(E13)-COLUMN($D$8)+1,ROW(E13)-ROW($D$8)+1)} -> 0.25 | F13: {=1/INDEX($D$8:$O$19,COLUMN(F13)-COLUMN($D$8)+1,ROW(F13)-ROW($D$8)+1)} -> 0.25 | G13: {=1/INDEX($D$8:$O$19,COLUMN(G13)-COLUMN($D$8)+1,ROW(G13)-ROW($D$8)+1)} -> 0.2 | H13: {=1/INDEX($D$8:$O$19,COLUMN(H13)-COLUMN($D$8)+1,ROW(H13)-ROW($D$8)+1)} -> 0.25 | I13: 1 | J13: 2 | K13: 2 | L13: 3 | M13: 4 | N13: 4 | O13: 5
C14: =C13+5 -> 10 | D14: {=1/INDEX($D$8:$O$19,COLUMN(D14)-COLUMN($D$8)+1,ROW(D14)-ROW($D$8)+1)} -> 0.16666667 | E14: {=1/INDEX($D$8:$O$19,COLUMN(E14)-COLUMN($D$8)+1,ROW(E14)-ROW($D$8)+1)} -> 0.2 | F14: {=1/INDEX($D$8:$O$19,COLUMN(F14)-COLUMN($D$8)+1,ROW(F14)-ROW($D$8)+1)} -> 0.25 | G14: {=1/INDEX($D$8:$O$19,COLUMN(G14)-COLUMN($D$8)+1,ROW(G14)-ROW($D$8)+1)} -> 0.2 | H14: {=1/INDEX($D$8:$O$19,COLUMN(H14)-COLUMN($D$8)+1,ROW(H14)-ROW($D$8)+1)} -> 0.25 | I14: {=1/INDEX($D$8:$O$19,COLUMN(I14)-COLUMN($D$8)+1,ROW(I14)-ROW($D$8)+1)} -> 0.5 | J14: 1 | K14: 2 | L14: 2 | M14: 2 | N14: 3 | O14: 3
C15: =C14+5 -> 15 | D15: {=1/INDEX($D$8:$O$19,COLUMN(D15)-COLUMN($D$8)+1,ROW(D15)-ROW($D$8)+1)} -> 0.14285714 | E15: {=1/INDEX($D$8:$O$19,COLUMN(E15)-COLUMN($D$8)+1,ROW(E15)-ROW($D$8)+1)} -> 0.16666667 | F15: {=1/INDEX($D$8:$O$19,COLUMN(F15)-COLUMN($D$8)+1,ROW(F15)-ROW($D$8)+1)} -> 0.2 | G15: {=1/INDEX($D$8:$O$19,COLUMN(G15)-COLUMN($D$8)+1,ROW(G15)-ROW($D$8)+1)} -> 0.16666667 | H15: {=1/INDEX($D$8:$O$19,COLUMN(H15)-COLUMN($D$8)+1,ROW(H15)-ROW($D$8)+1)} -> 0.2 | I15: {=1/INDEX($D$8:$O$19,COLUMN(I15)-COLUMN($D$8)+1,ROW(I15)-ROW($D$8)+1)} -> 0.5 | J15: {=1/INDEX($D$8:$O$19,COLUMN(J15)-COLUMN($D$8)+1,ROW(J15)-ROW($D$8)+1)} -> 0.5 | K15: 1 | L15: 1 | M15: 1 | N15: 1 | O15: 2
C16: =C15+5 -> 20 | D16: {=1/INDEX($D$8:$O$19,COLUMN(D16)-COLUMN($D$8)+1,ROW(D16)-ROW($D$8)+1)} -> 0.125 | E16: {=1/INDEX($D$8:$O$19,COLUMN(E16)-COLUMN($D$8)+1,ROW(E16)-ROW($D$8)+1)} -> 0.14285714 | F16: {=1/INDEX($D$8:$O$19,COLUMN(F16)-COLUMN($D$8)+1,ROW(F16)-ROW($D$8)+1)} -> 0.16666667 | G16: {=1/INDEX($D$8:$O$19,COLUMN(G16)-COLUMN($D$8)+1,ROW(G16)-ROW($D$8)+1)} -> 0.16666667 | H16: {=1/INDEX($D$8:$O$19,COLUMN(H16)-COLUMN($D$8)+1,ROW(H16)-ROW($D$8)+1)} -> 0.16666667 | I16: {=1/INDEX($D$8:$O$19,COLUMN(I16)-COLUMN($D$8)+1,ROW(I16)-ROW($D$8)+1)} -> 0.33333333 | J16: {=1/INDEX($D$8:$O$19,COLUMN(J16)-COLUMN($D$8)+1,ROW(J16)-ROW($D$8)+1)} -> 0.5 | K16: {=1/INDEX($D$8:$O$19,COLUMN(K16)-COLUMN($D$8)+1,ROW(K16)-ROW($D$8)+1)} -> 1 | L16: 1 | M16: 1 | N16: 1 | O16: 2
C17: =C16+5 -> 25 | D17: {=1/INDEX($D$8:$O$19,COLUMN(D17)-COLUMN($D$8)+1,ROW(D17)-ROW($D$8)+1)} -> 0.125 | E17: {=1/INDEX($D$8:$O$19,COLUMN(E17)-COLUMN($D$8)+1,ROW(E17)-ROW($D$8)+1)} -> 0.125 | F17: {=1/INDEX($D$8:$O$19,COLUMN(F17)-COLUMN($D$8)+1,ROW(F17)-ROW($D$8)+1)} -> 0.14285714 | G17: {=1/INDEX($D$8:$O$19,COLUMN(G17)-COLUMN($D$8)+1,ROW(G17)-ROW($D$8)+1)} -> 0.14285714 | H17: {=1/INDEX($D$8:$O$19,COLUMN(H17)-COLUMN($D$8)+1,ROW(H17)-ROW($D$8)+1)} -> 0.14285714 | I17: {=1/INDEX($D$8:$O$19,COLUMN(I17)-COLUMN($D$8)+1,ROW(I17)-ROW($D$8)+1)} -> 0.25 | J17: {=1/INDEX($D$8:$O$19,COLUMN(J17)-COLUMN($D$8)+1,ROW(J17)-ROW($D$8)+1)} -> 0.5 | K17: {=1/INDEX($D$8:$O$19,COLUMN(K17)-COLUMN($D$8)+1,ROW(K17)-ROW($D$8)+1)} -> 1 | L17: {=1/INDEX($D$8:$O$19,COLUMN(L17)-COLUMN($D$8)+1,ROW(L17)-ROW($D$8)+1)} -> 1 | M17: 1 | N17: 1 | O17: 1
C18: =C17+5 -> 30 | D18: {=1/INDEX($D$8:$O$19,COLUMN(D18)-COLUMN($D$8)+1,ROW(D18)-ROW($D$8)+1)} -> 0.11111111 | E18: {=1/INDEX($D$8:$O$19,COLUMN(E18)-COLUMN($D$8)+1,ROW(E18)-ROW($D$8)+1)} -> 0.125 | F18: {=1/INDEX($D$8:$O$19,COLUMN(F18)-COLUMN($D$8)+1,ROW(F18)-ROW($D$8)+1)} -> 0.125 | G18: {=1/INDEX($D$8:$O$19,COLUMN(G18)-COLUMN($D$8)+1,ROW(G18)-ROW($D$8)+1)} -> 0.125 | H18: {=1/INDEX($D$8:$O$19,COLUMN(H18)-COLUMN($D$8)+1,ROW(H18)-ROW($D$8)+1)} -> 0.14285714 | I18: {=1/INDEX($D$8:$O$19,COLUMN(I18)-COLUMN($D$8)+1,ROW(I18)-ROW($D$8)+1)} -> 0.25 | J18: {=1/INDEX($D$8:$O$19,COLUMN(J18)-COLUMN($D$8)+1,ROW(J18)-ROW($D$8)+1)} -> 0.33333333 | K18: {=1/INDEX($D$8:$O$19,COLUMN(K18)-COLUMN($D$8)+1,ROW(K18)-ROW($D$8)+1)} -> 1 | ... M18: {=1/INDEX($D$8:$O$19,COLUMN(M18)-COLUMN($D$8)+1,ROW(M18)-ROW($D$8)+1)} -> 1 | N18: 1 | O18: 1
C19: =C18+5 -> 35 | D19: {=1/INDEX($D$8:$O$19,COLUMN(D19)-COLUMN($D$8)+1,ROW(D19)-ROW($D$8)+1)} -> 0.11111111 | E19: {=1/INDEX($D$8:$O$19,COLUMN(E19)-COLUMN($D$8)+1,ROW(E19)-ROW($D$8)+1)} -> 0.11111111 | F19: {=1/INDEX($D$8:$O$19,COLUMN(F19)-COLUMN($D$8)+1,ROW(F19)-ROW($D$8)+1)} -> 0.11111111 | G19: {=1/INDEX($D$8:$O$19,COLUMN(G19)-COLUMN($D$8)+1,ROW(G19)-ROW($D$8)+1)} -> 0.11111111 | H19: {=1/INDEX($D$8:$O$19,COLUMN(H19)-COLUMN($D$8)+1,ROW(H19)-ROW($D$8)+1)} -> 0.125 | I19: {=1/INDEX($D$8:$O$19,COLUMN(I19)-COLUMN($D$8)+1,ROW(I19)-ROW($D$8)+1)} -> 0.2 | J19: {=1/INDEX($D$8:$O$19,COLUMN(J19)-COLUMN($D$8)+1,ROW(J19)-ROW($D$8)+1)} -> 0.33333333 | K19: {=1/INDEX($D$8:$O$19,COLUMN(K19)-COLUMN($D$8)+1,ROW(K19)-ROW($D$8)+1)} -> 0.5 | ... N19: {=1/INDEX($D$8:$O$19,COLUMN(N19)-COLUMN($D$8)+1,ROW(N19)-ROW($D$8)+1)} -> 1 | O19: 1
C22: Таблица попарных сравнений по отношению к свойству "прохладно"
D23: -20 | E23: -15 | F23: =E23+5 -> -10 | G23: =F23+5 -> -5 | H23: =G23+5 -> 0 | I23: =H23+5 -> 5 | J23: =I23+5 -> 10 | K23: =J23+5 -> 15 | L23: =K23+5 -> 20 | M23: =L23+5 -> 25 | ... O23: =N23+5 -> 35
C24: =-20 -> -20 | D24: 1 | E24: 2 | F24: 3 | G24: 4 | H24: 5 | I24: 6 | J24: 7 | K24: 8 | L24: 8 | M24: 8 | N24: 9 | O24: 9
C25: =C24+5 -> -15 | D25: {=1/INDEX($D$24:$O$35,COLUMN(D25)-COLUMN($D$24)+1,ROW(D25)-ROW($D$24)+1)} -> 0.5 | E25: 1 | F25: 1 | G25: 2 | H25: 3 | I25: 4 | J25: 4 | K25: 5 | L25: 6 | M25: 7 | N25: 8 | O25: 9
C26: =C25+5 -> -10 | D26: {=1/INDEX($D$24:$O$35,COLUMN(D26)-COLUMN($D$24)+1,ROW(D26)-ROW($D$24)+1)} -> 0.33333333 | E26: {=1/INDEX($D$24:$O$35,COLUMN(E26)-COLUMN($D$24)+1,ROW(E26)-ROW($D$24)+1)} -> 1 | F26: 1 | G26: 1 | H26: 2 | I26: 3 | J26: 4 | K26: 5 | L26: 6 | M26: 7 | N26: 8 | O26: 9
C27: =C26+5 -> -5 | D27: {=1/INDEX($D$24:$O$35,COLUMN(D27)-COLUMN($D$24)+1,ROW(D27)-ROW($D$24)+1)} -> 0.25 | E27: {=1/INDEX($D$24:$O$35,COLUMN(E27)-COLUMN($D$24)+1,ROW(E27)-ROW($D$24)+1)} -> 0.5 | F27: {=1/INDEX($D$24:$O$35,COLUMN(F27)-COLUMN($D$24)+1,ROW(F27)-ROW($D$24)+1)} -> 1 | G27: 1 | H27: 2 | I27: 3 | J27: 4 | K27: 5 | L27: 6 | M27: 7 | N27: 8 | O27: 9
C28: =C27+5 -> 0 | D28: {=1/INDEX($D$24:$O$35,COLUMN(D28)-COLUMN($D$24)+1,ROW(D28)-ROW($D$24)+1)} -> 0.2 | E28: {=1/INDEX($D$24:$O$35,COLUMN(E28)-COLUMN($D$24)+1,ROW(E28)-ROW($D$24)+1)} -> 0.33333333 | F28: {=1/INDEX($D$24:$O$35,COLUMN(F28)-COLUMN($D$24)+1,ROW(F28)-ROW($D$24)+1)} -> 0.5 | G28: {=1/INDEX($D$24:$O$35,COLUMN(G28)-COLUMN($D$24)+1,ROW(G28)-ROW($D$24)+1)} -> 0.5 | H28: 1 | I28: 3 | J28: 4 | K28: 5 | L28: 6 | M28: 7 | N28: 8 | O28: 9
C29: =C28+5 -> 5 | D29: {=1/INDEX($D$24:$O$35,COLUMN(D29)-COLUMN($D$24)+1,ROW(D29)-ROW($D$24)+1)} -> 0.16666667 | E29: {=1/INDEX($D$24:$O$35,COLUMN(E29)-COLUMN($D$24)+1,ROW(E29)-ROW($D$24)+1)} -> 0.25 | F29: {=1/INDEX($D$24:$O$35,COLUMN(F29)-COLUMN($D$24)+1,ROW(F29)-ROW($D$24)+1)} -> 0.33333333 | G29: {=1/INDEX($D$24:$O$35,COLUMN(G29)-COLUMN($D$24)+1,ROW(G29)-ROW($D$24)+1)} -> 0.33333333 | H29: {=1/INDEX($D$24:$O$35,COLUMN(H29)-COLUMN($D$24)+1,ROW(H29)-ROW($D$24)+1)} -> 0.33333333 | I29: 1 | J29: 3 | K29: 3 | L29: 4 | M29: 5 | N29: 6 | O29: 6
C30: =C29+5 -> 10 | D30: {=1/INDEX($D$24:$O$35,COLUMN(D30)-COLUMN($D$24)+1,ROW(D30)-ROW($D$24)+1)} -> 0.14285714 | E30: {=1/INDEX($D$24:$O$35,COLUMN(E30)-COLUMN($D$24)+1,ROW(E30)-ROW($D$24)+1)} -> 0.25 | F30: {=1/INDEX($D$24:$O$35,COLUMN(F30)-COLUMN($D$24)+1,ROW(F30)-ROW($D$24)+1)} -> 0.25 | G30: {=1/INDEX($D$24:$O$35,COLUMN(G30)-COLUMN($D$24)+1,ROW(G30)-ROW($D$24)+1)} -> 0.25 | H30: {=1/INDEX($D$24:$O$35,COLUMN(H30)-COLUMN($D$24)+1,ROW(H30)-ROW($D$24)+1)} -> 0.25 | I30: {=1/INDEX($D$24:$O$35,COLUMN(I30)-COLUMN($D$24)+1,ROW(I30)-ROW($D$24)+1)} -> 0.33333333 | J30: 1 | K30: 2 | L30: 2 | M30: 3 | N30: 3 | O30: 3
C31: =C30+5 -> 15 | D31: {=1/INDEX($D$24:$O$35,COLUMN(D31)-COLUMN($D$24)+1,ROW(D31)-ROW($D$24)+1)} -> 0.125 | E31: {=1/INDEX($D$24:$O$35,COLUMN(E31)-COLUMN($D$24)+1,ROW(E31)-ROW($D$24)+1)} -> 0.2 | F31: {=1/INDEX($D$24:$O$35,COLUMN(F31)-COLUMN($D$24)+1,ROW(F31)-ROW($D$24)+1)} -> 0.2 | G31: {=1/INDEX($D$24:$O$35,COLUMN(G31)-COLUMN($D$24)+1,ROW(G31)-ROW($D$24)+1)} -> 0.2 | H31: {=1/INDEX($D$24:$O$35,COLUMN(H31)-COLUMN($D$24)+1,ROW(H31)-ROW($D$24)+1)} -> 0.2 | I31: {=1/INDEX($D$24:$O$35,COLUMN(I31)-COLUMN($D$24)+1,ROW(I31)-ROW($D$24)+1)} -> 0.33333333 | J31: {=1/INDEX($D$24:$O$35,COLUMN(J31)-COLUMN($D$24)+1,ROW(J31)-ROW($D$24)+1)} -> 0.5 | K31: 1 | L31: 1 | M31: 1 | N31: 2 | O31: 2
C32: =C31+5 -> 20 | D32: {=1/INDEX($D$24:$O$35,COLUMN(D32)-COLUMN($D$24)+1,ROW(D32)-ROW($D$24)+1)} -> 0.125 | E32: {=1/INDEX($D$24:$O$35,COLUMN(E32)-COLUMN($D$24)+1,ROW(E32)-ROW($D$24)+1)} -> 0.16666667 | F32: {=1/INDEX($D$24:$O$35,COLUMN(F32)-COLUMN($D$24)+1,ROW(F32)-ROW($D$24)+1)} -> 0.16666667 | G32: {=1/INDEX($D$24:$O$35,COLUMN(G32)-COLUMN($D$24)+1,ROW(G32)-ROW($D$24)+1)} -> 0.16666667 | H32: {=1/INDEX($D$24:$O$35,COLUMN(H32)-COLUMN($D$24)+1,ROW(H32)-ROW($D$24)+1)} -> 0.16666667 | I32: {=1/INDEX($D$24:$O$35,COLUMN(I32)-COLUMN($D$24)+1,ROW(I32)-ROW($D$24)+1)} -> 0.25 | J32: {=1/INDEX($D$24:$O$35,COLUMN(J32)-COLUMN($D$24)+1,ROW(J32)-ROW($D$24)+1)} -> 0.5 | K32: {=1/INDEX($D$24:$O$35,COLUMN(K32)-COLUMN($D$24)+1,ROW(K32)-ROW($D$24)+1)} -> 1 | L32: 1 | M32: 1 | N32: 1 | O32: 2
C33: =C32+5 -> 25 | D33: {=1/INDEX($D$24:$O$35,COLUMN(D33)-COLUMN($D$24)+1,ROW(D33)-ROW($D$24)+1)} -> 0.125 | E33: {=1/INDEX($D$24:$O$35,COLUMN(E33)-COLUMN($D$24)+1,ROW(E33)-ROW($D$24)+1)} -> 0.14285714 | F33: {=1/INDEX($D$24:$O$35,COLUMN(F33)-COLUMN($D$24)+1,ROW(F33)-ROW($D$24)+1)} -> 0.14285714 | G33: {=1/INDEX($D$24:$O$35,COLUMN(G33)-COLUMN($D$24)+1,ROW(G33)-ROW($D$24)+1)} -> 0.14285714 | H33: {=1/INDEX($D$24:$O$35,COLUMN(H33)-COLUMN($D$24)+1,ROW(H33)-ROW($D$24)+1)} -> 0.14285714 | I33: {=1/INDEX($D$24:$O$35,COLUMN(I33)-COLUMN($D$24)+1,ROW(I33)-ROW($D$24)+1)} -> 0.2 | J33: {=1/INDEX($D$24:$O$35,COLUMN(J33)-COLUMN($D$24)+1,ROW(J33)-ROW($D$24)+1)} -> 0.33333333 | K33: {=1/INDEX($D$24:$O$35,COLUMN(K33)-COLUMN($D$24)+1,ROW(K33)-ROW($D$24)+1)} -> 1 | L33: {=1/INDEX($D$24:$O$35,COLUMN(L33)-COLUMN($D$24)+1,ROW(L33)-ROW($D$24)+1)} -> 1 | M33: 1 | N33: {=1/INDEX($D$24:$O$35,COLUMN(N33)-COLUMN($D$24)+1,ROW(N33)-ROW($D$24)+1)} -> 1 | O33: 1
C34: =C33+5 -> 30 | D34: {=1/INDEX($D$24:$O$35,COLUMN(D34)-COLUMN($D$24)+1,ROW(D34)-ROW($D$24)+1)} -> 0.11111111 | E34: {=1/INDEX($D$24:$O$35,COLUMN(E34)-COLUMN($D$24)+1,ROW(E34)-ROW($D$24)+1)} -> 0.125 | F34: {=1/INDEX($D$24:$O$35,COLUMN(F34)-COLUMN($D$24)+1,ROW(F34)-ROW($D$24)+1)} -> 0.125 | G34: {=1/INDEX($D$24:$O$35,COLUMN(G34)-COLUMN($D$24)+1,ROW(G34)-ROW($D$24)+1)} -> 0.125 | H34: {=1/INDEX($D$24:$O$35,COLUMN(H34)-COLUMN($D$24)+1,ROW(H34)-ROW($D$24)+1)} -> 0.125 | I34: {=1/INDEX($D$24:$O$35,COLUMN(I34)-COLUMN($D$24)+1,ROW(I34)-ROW($D$24)+1)} -> 0.16666667 | J34: {=1/INDEX($D$24:$O$35,COLUMN(J34)-COLUMN($D$24)+1,ROW(J34)-ROW($D$24)+1)} -> 0.33333333 | K34: {=1/INDEX($D$24:$O$35,COLUMN(K34)-COLUMN($D$24)+1,ROW(K34)-ROW($D$24)+1)} -> 0.5 | L34: {=1/INDEX($D$24:$O$35,COLUMN(L34)-COLUMN($D$24)+1,ROW(L34)-ROW($D$24)+1)} -> 1 | M34: 1 | N34: 1 | O34: 1
C35: =C34+5 -> 35 | D35: {=1/INDEX($D$24:$O$35,COLUMN(D35)-COLUMN($D$24)+1,ROW(D35)-ROW($D$24)+1)} -> 0.11111111 | E35: {=1/INDEX($D$24:$O$35,COLUMN(E35)-COLUMN($D$24)+1,ROW(E35)-ROW($D$24)+1)} -> 0.11111111 | F35: {=1/INDEX($D$24:$O$35,COLUMN(F35)-COLUMN($D$24)+1,ROW(F35)-ROW($D$24)+1)} -> 0.11111111 | G35: {=1/INDEX($D$24:$O$35,COLUMN(G35)-COLUMN($D$24)+1,ROW(G35)-ROW($D$24)+1)} -> 0.11111111 | H35: {=1/INDEX($D$24:$O$35,COLUMN(H35)-COLUMN($D$24)+1,ROW(H35)-ROW($D$24)+1)} -> 0.11111111 | I35: {=1/INDEX($D$24:$O$35,COLUMN(I35)-COLUMN($D$24)+1,ROW(I35)-ROW($D$24)+1)} -> 0.16666667 | J35: {=1/INDEX($D$24:$O$35,COLUMN(J35)-COLUMN($D$24)+1,ROW(J35)-ROW($D$24)+1)} -> 0.33333333 | K35: {=1/INDEX($D$24:$O$35,COLUMN(K35)-COLUMN($D$24)+1,ROW(K35)-ROW($D$24)+1)} -> 0.5 | ... M35: {=1/INDEX($D$24:$O$35,COLUMN(M35)-COLUMN($D$24)+1,ROW(M35)-ROW($D$24)+1)} -> 1 | N35: 1 | O35: 1
C38: Таблица попарных сравнений по отношению к свойству "умеренно"
D39: -20 | E39: -15 | F39: =E39+5 -> -10 | G39: =F39+5 -> -5 | H39: =G39+5 -> 0 | I39: =H39+5 -> 5 | J39: =I39+5 -> 10 | K39: =J39+5 -> 15 | L39: =K39+5 -> 20 | M39: =L39+5 -> 25 | ... O39: =N39+5 -> 35
C40: =-20 -> -20 | D40: 1 | E40: {=1/INDEX('lab6'!$D$40:$O$51,COLUMN(E40) - COLUMN('lab6'!$D$40)+1,ROW(E40)-ROW('lab6'!$D$40)+1)} -> 1 | F40: {=1/INDEX('lab6'!$D$40:$O$51,COLUMN(F40) - COLUMN('lab6'!$D$40)+1,ROW(F40)-ROW('lab6'!$D$40)+1)} -> 1 | G40: {=1/INDEX('lab6'!$D$40:$O$51,COLUMN(G40) - COLUMN('lab6'!$D$40)+1,ROW(G40)-ROW('lab6'!$D$40)+1)} -> 0.5 | H40: {=1/INDEX('lab6'!$D$40:$O$51,COLUMN(H40) - COLUMN('lab6'!$D$40)+1,ROW(H40)-ROW('lab6'!$D$40)+1)} -> 0.33333333 | I40: {=1/INDEX('lab6'!$D$40:$O$51,COLUMN(I40) - COLUMN('lab6'!$D$40)+1,ROW(I40)-ROW('lab6'!$D$40)+1)} -> 0.25 | J40: {=1/INDEX('lab6'!$D$40:$O$51,COLUMN(J40) - COLUMN('lab6'!$D$40)+1,ROW(J40)-ROW('lab6'!$D$40)+1)} -> 0.2 | K40: {=1/INDEX('lab6'!$D$40:$O$51,COLUMN(K40) - COLUMN('lab6'!$D$40)+1,ROW(K40)-ROW('lab6'!$D$40)+1)} -> 0.125 | L40: {=1/INDEX('lab6'!$D$40:$O$51,COLUMN(L40) - COLUMN('lab6'!$D$40)+1,ROW(L40)-ROW('lab6'!$D$40)+1)} -> 0.14285714 | ... O40: {=1/INDEX('lab6'!$D$40:$O$51,COLUMN(O40) - COLUMN('lab6'!$D$40)+1,ROW(O40)-ROW('lab6'!$D$40)+1)} -> 0.5
C41: =C40+5 -> -15 | D41: 1 | E41: 1 | F41: {=1/INDEX('lab6'!$D$40:$O$51,COLUMN(F41) - COLUMN('lab6'!$D$40)+1,ROW(F41)-ROW('lab6'!$D$40)+1)} -> 1 | G41: {=1/INDEX('lab6'!$D$40:$O$51,COLUMN(G41) - COLUMN('lab6'!$D$40)+1,ROW(G41)-ROW('lab6'!$D$40)+1)} -> 0.5 | H41: {=1/INDEX('lab6'!$D$40:$O$51,COLUMN(H41) - COLUMN('lab6'!$D$40)+1,ROW(H41)-ROW('lab6'!$D$40)+1)} -> 0.33333333 | I41: {=1/INDEX('lab6'!$D$40:$O$51,COLUMN(I41) - COLUMN('lab6'!$D$40)+1,ROW(I41)-ROW('lab6'!$D$40)+1)} -> 0.25 | J41: {=1/INDEX('lab6'!$D$40:$O$51,COLUMN(J41) - COLUMN('lab6'!$D$40)+1,ROW(J41)-ROW('lab6'!$D$40)+1)} -> 0.2 | K41: {=1/INDEX('lab6'!$D$40:$O$51,COLUMN(K41) - COLUMN('lab6'!$D$40)+1,ROW(K41)-ROW('lab6'!$D$40)+1)} -> 0.125 | L41: {=1/INDEX('lab6'!$D$40:$O$51,COLUMN(L41) - COLUMN('lab6'!$D$40)+1,ROW(L41)-ROW('lab6'!$D$40)+1)} -> 0.14285714 | M41: {=1/INDEX('lab6'!$D$40:$O$51,COLUMN(M41) - COLUMN('lab6'!$D$40)+1,ROW(M41)-ROW('lab6'!$D$40)+1)} -> 0.16666667 | ... O41: {=1/INDEX('lab6'!$D$40:$O$51,COLUMN(O41) - COLUMN('lab6'!$D$40)+1,ROW(O41)-ROW('lab6'!$D$40)+1)} -> 0.5
C42: =C41+5 -> -10 | D42: 1 | E42: 1 | F42: 1 | G42: {=1/INDEX('lab6'!$D$40:$O$51,COLUMN(G42) - COLUMN('lab6'!$D$40)+1,ROW(G42)-ROW('lab6'!$D$40)+1)} -> 0.5 | H42: {=1/INDEX('lab6'!$D$40:$O$51,COLUMN(H42) - COLUMN('lab6'!$D$40)+1,ROW(H42)-ROW('lab6'!$D$40)+1)} -> 0.33333333 | I42: {=1/INDEX('lab6'!$D$40:$O$51,COLUMN(I42) - COLUMN('lab6'!$D$40)+1,ROW(I42)-ROW('lab6'!$D$40)+1)} -> 0.25 | J42: {=1/INDEX('lab6'!$D$40:$O$51,COLUMN(J42) - COLUMN('lab6'!$D$40)+1,ROW(J42)-ROW('lab6'!$D$40)+1)} -> 0.2 | K42: {=1/INDEX('lab6'!$D$40:$O$51,COLUMN(K42) - COLUMN('lab6'!$D$40)+1,ROW(K42)-ROW('lab6'!$D$40)+1)} -> 0.14285714 | L42: {=1/INDEX('lab6'!$D$40:$O$51,COLUMN(L42) - COLUMN('lab6'!$D$40)+1,ROW(L42)-ROW('lab6'!$D$40)+1)} -> 0.16666667 | M42: {=1/INDEX('lab6'!$D$40:$O$51,COLUMN(M42) - COLUMN('lab6'!$D$40)+1,ROW(M42)-ROW('lab6'!$D$40)+1)} -> 0.2 | N42: {=1/INDEX('lab6'!$D$40:$O$51,COLUMN(N42) - COLUMN('lab6'!$D$40)+1,ROW(N42)-ROW('lab6'!$D$40)+1)} -> 0.25 | O42: {=1/INDEX('lab6'!$D$40:$O$51,COLUMN(O42) - COLUMN('lab6'!$D$40)+1,ROW(O42)-ROW('lab6'!$D$40)+1)} -> 0.33333333
C43: =C42+5 -> -5 | D43: 2 | E43: 2 | F43: 2 | G43: 1 | H43: {=1/INDEX('lab6'!$D$40:$O$51,COLUMN(H43) - COLUMN('lab6'!$D$40)+1,ROW(H43)-ROW('lab6'!$D$40)+1)} -> 0.33333333 | I43: {=1/INDEX('lab6'!$D$40:$O$51,COLUMN(I43) - COLUMN('lab6'!$D$40)+1,ROW(I43)-ROW('lab6'!$D$40)+1)} -> 0.33333333 | J43: {=1/INDEX('lab6'!$D$40:$O$51,COLUMN(J43) - COLUMN('lab6'!$D$40)+1,ROW(J43)-ROW('lab6'!$D$40)+1)} -> 0.25 | K43: {=1/INDEX('lab6'!$D$40:$O$51,COLUMN(K43) - COLUMN('lab6'!$D$40)+1,ROW(K43)-ROW('lab6'!$D$40)+1)} -> 0.14285714 | L43: {=1/INDEX('lab6'!$D$40:$O$51,COLUMN(L43) - COLUMN('lab6'!$D$40)+1,ROW(L43)-ROW('lab6'!$D$40)+1)} -> 0.16666667 | M43: {=1/INDEX('lab6'!$D$40:$O$51,COLUMN(M43) - COLUMN('lab6'!$D$40)+1,ROW(M43)-ROW('lab6'!$D$40)+1)} -> 0.2 | N43: {=1/INDEX('lab6'!$D$40:$O$51,COLUMN(N43) - COLUMN('lab6'!$D$40)+1,ROW(N43)-ROW('lab6'!$D$40)+1)} -> 0.2 | O43: {=1/INDEX('lab6'!$D$40:$O$51,COLUMN(O43) - COLUMN('lab6'!$D$40)+1,ROW(O43)-ROW('lab6'!$D$40)+1)} -> 0.33333333
C44: =C43+5 -> 0 | D44: 3 | E44: 3 | F44: 3 | G44: 3 | H44: 1 | I44: {=1/INDEX('lab6'!$D$40:$O$51,COLUMN(I44) - COLUMN('lab6'!$D$40)+1,ROW(I44)-ROW('lab6'!$D$40)+1)} -> 0.33333333 | J44: {=1/INDEX('lab6'!$D$40:$O$51,COLUMN(J44) - COLUMN('lab6'!$D$40)+1,ROW(J44)-ROW('lab6'!$D$40)+1)} -> 0.16666667 | K44: {=1/INDEX('lab6'!$D$40:$O$51,COLUMN(K44) - COLUMN('lab6'!$D$40)+1,ROW(K44)-ROW('lab6'!$D$40)+1)} -> 0.125 | L44: {=1/INDEX('lab6'!$D$40:$O$51,COLUMN(L44) - COLUMN('lab6'!$D$40)+1,ROW(L44)-ROW('lab6'!$D$40)+1)} -> 0.16666667 | M44: {=1/INDEX('lab6'!$D$40:$O$51,COLUMN(M44) - COLUMN('lab6'!$D$40)+1,ROW(M44)-ROW('lab6'!$D$40)+1)} -> 0.2 | N44: {=1/INDEX('lab6'!$D$40:$O$51,COLUMN(N44) - COLUMN('lab6'!$D$40)+1,ROW(N44)-ROW('lab6'!$D$40)+1)} -> 0.2 | O44: {=1/INDEX('lab6'!$D$40:$O$51,COLUMN(O44) - COLUMN('lab6'!$D$40)+1,ROW(O44)-ROW('lab6'!$D$40)+1)} -> 0.33333333
C45: =C44+5 -> 5 | D45: 4 | E45: 4 | F45: 4 | G45: 3 | H45: 3 | I45: 1 | J45: {=1/INDEX('lab6'!$D$40:$O$51,COLUMN(J45) - COLUMN('lab6'!$D$40)+1,ROW(J45)-ROW('lab6'!$D$40)+1)} -> 0.25 | K45: {=1/INDEX('lab6'!$D$40:$O$51,COLUMN(K45) - COLUMN('lab6'!$D$40)+1,ROW(K45)-ROW('lab6'!$D$40)+1)} -> 0.14285714 | L45: {=1/INDEX('lab6'!$D$40:$O$51,COLUMN(L45) - COLUMN('lab6'!$D$40)+1,ROW(L45)-ROW('lab6'!$D$40)+1)} -> 0.16666667 | M45: {=1/INDEX('lab6'!$D$40:$O$51,COLUMN(M45) - COLUMN('lab6'!$D$40)+1,ROW(M45)-ROW('lab6'!$D$40)+1)} -> 0.2 | N45: {=1/INDEX('lab6'!$D$40:$O$51,COLUMN(N45) - COLUMN('lab6'!$D$40)+1,ROW(N45)-ROW('lab6'!$D$40)+1)} -> 0.25 | O45: {=1/INDEX('lab6'!$D$40:$O$51,COLUMN(O45) - COLUMN('lab6'!$D$40)+1,ROW(O45)-ROW('lab6'!$D$40)+1)} -> 0.33333333
C46: =C45+5 -> 10 | D46: 5 | E46: 5 | F46: 5 | G46: 4 | H46: 6 | I46: 4 | J46: 1 | K46: {=1/INDEX('lab6'!$D$40:$O$51,COLUMN(K46) - COLUMN('lab6'!$D$40)+1,ROW(K46)-ROW('lab6'!$D$40)+1)} -> 0.33333333 | L46: {=1/INDEX('lab6'!$D$40:$O$51,COLUMN(L46) - COLUMN('lab6'!$D$40)+1,ROW(L46)-ROW('lab6'!$D$40)+1)} -> 0.2 | M46: {=1/INDEX('lab6'!$D$40:$O$51,COLUMN(M46) - COLUMN('lab6'!$D$40)+1,ROW(M46)-ROW('lab6'!$D$40)+1)} -> 0.2 | N46: {=1/INDEX('lab6'!$D$40:$O$51,COLUMN(N46) - COLUMN('lab6'!$D$40)+1,ROW(N46)-ROW('lab6'!$D$40)+1)} -> 0.25 | O46: {=1/INDEX('lab6'!$D$40:$O$51,COLUMN(O46) - COLUMN('lab6'!$D$40)+1,ROW(O46)-ROW('lab6'!$D$40)+1)} -> 0.33333333
C47: =C46+5 -> 15 | D47: 8 | E47: 8 | F47: 7 | G47: 7 | H47: 8 | I47: 7 | J47: 3 | K47: 1 | L47: {=1/INDEX('lab6'!$D$40:$O$51,COLUMN(L47) - COLUMN('lab6'!$D$40)+1,ROW(L47)-ROW('lab6'!$D$40)+1)} -> 0.5 | M47: {=1/INDEX('lab6'!$D$40:$O$51,COLUMN(M47) - COLUMN('lab6'!$D$40)+1,ROW(M47)-ROW('lab6'!$D$40)+1)} -> 0.33333333 | N47: {=1/INDEX('lab6'!$D$40:$O$51,COLUMN(N47) - COLUMN('lab6'!$D$40)+1,ROW(N47)-ROW('lab6'!$D$40)+1)} -> 0.5 | O47: {=1/INDEX('lab6'!$D$40:$O$51,COLUMN(O47) - COLUMN('lab6'!$D$40)+1,ROW(O47)-ROW('lab6'!$D$40)+1)} -> 0.5
C48: =C47+5 -> 20 | D48: 7 | E48: 7 | F48: 6 | G48: 6 | H48: 6 | I48: 6 | J48: 5 | K48: 2 | L48: 1 | M48: {=1/INDEX('lab6'!$D$40:$O$51,COLUMN(M48) - COLUMN('lab6'!$D$40)+1,ROW(M48)-ROW('lab6'!$D$40)+1)} -> 0.5 | N48: {=1/INDEX('lab6'!$D$40:$O$51,COLUMN(N48) - COLUMN('lab6'!$D$40)+1,ROW(N48)-ROW('lab6'!$D$40)+1)} -> 0.5 | O48: {=1/INDEX('lab6'!$D$40:$O$51,COLUMN(O48) - COLUMN('lab6'!$D$40)+1,ROW(O48)-ROW('lab6'!$D$40)+1)} -> 0.5
...
